Workbook
Name E14a116802: #REF!

Sheet Capa
A21: Relatório de Contas
A28: =DBase!$C$4 -> 45658

Sheet DBase
A2: PRESSUPOSTOS
B4: Ano: | C4: 45658
B6: Cliente: | C6: Mbolo Yeto
B8: NIF: | C8: 5000861677
C10: =C4 -> 45658 | D10: =C10-1 -> 45657
B12: N.º de Empregados | C12: 1 | D12: 1
B15: BALANÇO EM | E15: Datas de Fecho: | F15: =C4+364 -> 46022
B17: DEMONSTRAÇÃO DE RESULTADOS EM
B19: DEMONSTRAÇÃO DE FLUXOS DE CAIXA EM

Sheet TL
A1: Lançamentos | H1: =(SUM($H$2:$H$5400)-SUM($I$2:$I5401)) -> 0 | I1: =IF((SUM($I$2:$I$65983)-SUM($H$2:$H$65983))<>0,"DEB<>CRE","CONCLUÍDO") -> CONCLUÍDO
A2: Salários | C2: =+C157 -> 0 | D2: Pag_Sal | E2: 4511 | F2: =IF(E2>0,(VLOOKUP(E2,'Blnct AR'!$C$2:$D$2259,2,0))," ") -> Caixa Kwanza | G2: Salários Pagto | I2: 5383905
A3: =+A2 -> Salários | C3: =+C2 -> 0 | D3: =+D2 -> Pag_Sal | E3: 36111 | F3: =IF(E3>0,(VLOOKUP(E3,'Blnct AR'!$C$2:$D$2259,2,0))," ") -> Orgaõs sociais | G3: Salários Pagto | H3: 613350 | I3: 613350
A4: =+A3 -> Salários | C4: =+C3 -> 0 | D4: =+D3 -> Pag_Sal | E4: 36121 | F4: =IF(E4>0,(VLOOKUP(E4,'Blnct AR'!$C$2:$D$2259,2,0))," ") -> Empregados | G4: Salários Pagto | H4: 4034258 | I4: 4034258
A5: =+A4 -> Salários | C5: =+C3 -> 0 | D5: =+D3 -> Pag_Sal | E5: 72211 | F5: =IF(E5>0,(VLOOKUP(E5,'Blnct AR'!$C$2:$D$2259,2,0))," ") -> Ordenados | G5: Salários | H5: 4034258
A6: =+A5 -> Salários | C6: =+C4 -> 0 | D6: =+D4 -> Pag_Sal | E6: 7211 | F6: =IF(E6>0,(VLOOKUP(E6,'Blnct AR'!$C$2:$D$2259,2,0))," ") -> Ordenados | G6: Salários | H6: 613350
A7: =+A6 -> Salários | C7: =+C5 -> 0 | D7: =+D5 -> Pag_Sal | E7: 7214 | F7: =IF(E7>0,(VLOOKUP(E7,'Blnct AR'!$C$2:$D$2259,2,0))," ") -> Subsídio de natal | G7: Salários | H7: 0
A8: =+A7 -> Salários | C8: =+C6 -> 0 | D8: =+D6 -> Pag_Sal | E8: 72215 | F8: =IF(E8>0,(VLOOKUP(E8,'Blnct AR'!$C$2:$D$2259,2,0))," ") -> Subsídio de alimentação | G8: Salários | H8: 0
A9: =+A8 -> Salários | C9: =+C7 -> 0 | D9: =+D7 -> Pag_Sal | E9: 3431 | F9: =IF(E9>0,(VLOOKUP(E9,'Blnct AR'!$C$2:$D$2259,2,0))," ") -> IRT dependentes | G9: Salários IRT | H9: 198706 | I9: 198706
A10: =+A9 -> Salários | C10: =+C9 -> 0 | D10: =+D9 -> Pag_Sal | E10: 3452 | F10: =IF(E10>0,(VLOOKUP(E10,'Blnct AR'!$C$2:$D$2259,2,0))," ") -> IVA - Dedutível | G10: Salários INSS | H10: 127386 | I10: 127386
A11: =+A10 -> Salários | C11: =+C10 -> 0 | D11: =+D10 -> Pag_Sal | E11: 3451 | F11: =IF(E11>0,(VLOOKUP(E11,'Blnct AR'!$C$2:$D$2259,2,0))," ") -> IVA Suportado | G11: Salários INSS | H11: 22500 | I11: 22500
A12: =+A11 -> Salários | C12: =+C11 -> 0 | D12: =+D11 -> Pag_Sal | E12: 3453 | F12: =IF(E12>0,(VLOOKUP(E12,'Blnct AR'!$C$2:$D$2259,2,0))," ") -> IVA - Liquidado | G12: Salários INSS | H12: 387705 | I12: 387705
A13: =+A12 -> Salários | C13: =+C12 -> 0 | D13: =+D12 -> Pag_Sal | E13: 72521 | F13: =IF(E13>0,(VLOOKUP(E13,'Blnct AR'!$C$2:$D$2259,2,0))," ") -> Administrativo/outros | G13: Salários INSS (Trab.) | H13: 149886
A14: =+A13 -> Salários | C14: =+C13 -> 0 | D14: =+D13 -> Pag_Sal | E14: 72521 | F14: =IF(E14>0,(VLOOKUP(E14,'Blnct AR'!$C$2:$D$2259,2,0))," ") -> Administrativo/outros | G14: Salários IRT | H14: 198706
A15: =+A14 -> Salários | C15: =+C14 -> 0 | D15: =+D14 -> Pag_Sal | E15: 72511 | F15: =IF(E15>0,(VLOOKUP(E15,'Blnct AR'!$C$2:$D$2259,2,0))," ") -> #N/A | G15: Salários INSS (Ent.) | H15: 387705
A17: Subs_Natal | C17: =+C16 -> 0 | D17: Pag_Sal | E17: 4511 | F17: =IF(E17>0,(VLOOKUP(E17,'Blnct AR'!$C$2:$D$2259,2,0))," ") -> Caixa Kwanza | G17: Subsidio de Natal Pagto | I17: 20710
A18: =+A17 -> Subs_Natal | C18: =+C17 -> 0 | D18: Pag_Sal | E18: 7213 | F18: =IF(E18>0,(VLOOKUP(E18,'Blnct AR'!$C$2:$D$2259,2,0))," ") -> Subsídio de férias | G18: Subsidio de Natal | H18: 17270
A19: =+A18 -> Subs_Natal | C19: =+C18 -> 0 | D19: =+D18 -> Pag_Sal | E19: 72214 | F19: =IF(E19>0,(VLOOKUP(E19,'Blnct AR'!$C$2:$D$2259,2,0))," ") -> Subsídio de natal | G19: Subsidio de Natal | H19: 3440
A21: Subs_Férias | C21: =+C20 -> 0 | D21: Pag_Sal | E21: 4511 | F21: =IF(E21>0,(VLOOKUP(E21,'Blnct AR'!$C$2:$D$2259,2,0))," ") -> Caixa Kwanza | G21: Subsidio de Natal Pagto | I21: 20710
A22: =+A21 -> Subs_Férias | C22: =+C21 -> 0 | D22: Pag_Sal | E22: 7212 | F22: =IF(E22>0,(VLOOKUP(E22,'Blnct AR'!$C$2:$D$2259,2,0))," ") -> Subsídio de férias | G22: Subsidio de Férias | H22: 17270
A23: =+A22 -> Subs_Férias | C23: =+C22 -> 0 | D23: =+D22 -> Pag_Sal | E23: 72213 | F23: =IF(E23>0,(VLOOKUP(E23,'Blnct AR'!$C$2:$D$2259,2,0))," ") -> Subsídio de férias | G23: Subsidio de Férias | H23: 3440
F24: =IF(E24>0,(VLOOKUP(E24,'Blnct AR'!$C$2:$D$2259,2,0))," ")
A25: Imp_Selo | C25: =+C162 -> 0 | D25: Imp_Selo | E25: 34731334 | F25: =IF(E25>0,(VLOOKUP(E25,'Blnct AR'!$C$2:$D$2259,2,0))," ") -> IS - recibos outros | G25: Liquidação Imp. Selo | H25: 5000 | I25: 5000
A26: =+A25 -> Imp_Selo | C26: =+C25 -> 0 | D26: Imp_Selo | E26: 75311 | F26: =IF(E26>0,(VLOOKUP(E26,'Blnct AR'!$C$2:$D$2259,2,0))," ") -> Imposto de selo | G26: Liquidação Imp. Selo | H26: 5000
A27: =+A26 -> Imp_Selo | C27: =+C26 -> 0 | D27: Imp_Selo | E27: 4511 | F27: =IF(E27>0,(VLOOKUP(E27,'Blnct AR'!$C$2:$D$2259,2,0))," ") -> Caixa Kwanza | G27: Liquidação Imp. Selo | I27: 5000
F28: =IF(E28>0,(VLOOKUP(E28,'Blnct AR'!$C$2:$D$2259,2,0))," ")
A29: Tel_Net | C29: =+C28 -> 0 | D29: Dsp_FST | E29: 4511 | F29: =IF(E29>0,(VLOOKUP(E29,'Blnct AR'!$C$2:$D$2259,2,0))," ") -> Caixa Kwanza | G29: UNITEL Recarga | I29: 4500
A30: =+A29 -> Tel_Net | C30: =+C29 -> 0 | D30: Dsp_FST | E30: 75220 | F30: =IF(E30>0,(VLOOKUP(E30,'Blnct AR'!$C$2:$D$2259,2,0))," ") -> Comunicação | G30: UNITEL Recarga | H30: 4286
A31: =+A30 -> Tel_Net | C31: =+C30 -> 0 | D31: Dsp_FST | E31: 342121 | F31: =IF(E31>0,(VLOOKUP(E31,'Blnct AR'!$C$2:$D$2259,2,0))," ") -> IPC-LIQ.-PR.SERV.-TXRED-MERC. NAC. | G31: UNITEL Recarga | H31: 214 | I31: 214
A32: =+A31 -> Tel_Net | C32: =+C31 -> 0 | D32: Dsp_FST | E32: 75312 | F32: =IF(E32>0,(VLOOKUP(E32,'Blnct AR'!$C$2:$D$2259,2,0))," ") -> Imposto de Produção e Consumo | G32: UNITEL Recarga | H32: 214
F33: =IF(E33>0,(VLOOKUP(E33,'Blnct AR'!$C$2:$D$2259,2,0))," ")
A34: Gasolina | C34: =+C54 -> 0 | D34: Dsp_FST | E34: 4511 | F34: =IF(E34>0,(VLOOKUP(E34,'Blnct AR'!$C$2:$D$2259,2,0))," ") -> Caixa Kwanza | G34: Gasolina | I34: 5000
A35: =+A34 -> Gasolina | C35: =+C34 -> 0 | D35: Dsp_FST | E35: 752132 | F35: =IF(E35>0,(VLOOKUP(E35,'Blnct AR'!$C$2:$D$2259,2,0))," ") -> Gasolina | G35: Gasolina | H35: 5000
A37: Gás | C37: =+C57 -> 0 | D37: Dsp_FST | E37: 4511 | F37: =IF(E37>0,(VLOOKUP(E37,'Blnct AR'!$C$2:$D$2259,2,0))," ") -> Caixa Kwanza | G37: Gás | I37: 5000
A38: =+A37 -> Gás | C38: =+C37 -> 0 | D38: Dsp_FST | E38: 752133 | F38: =IF(E38>0,(VLOOKUP(E38,'Blnct AR'!$C$2:$D$2259,2,0))," ") -> Gás | G38: Gás | H38: 5000
A40: Água | C40: =+C57 -> 0 | D40: Dsp_FST | E40: 4511 | F40: =IF(E40>0,(VLOOKUP(E40,'Blnct AR'!$C$2:$D$2259,2,0))," ") -> Caixa Kwanza | G40: Água | I40: 5000
A41: =+A40 -> Água | C41: =+C40 -> 0 | D41: Dsp_FST | E41: 75211 | F41: =IF(E41>0,(VLOOKUP(E41,'Blnct AR'!$C$2:$D$2259,2,0))," ") -> Água | G41: Água | H41: 5000
A43: Eletricidade | C43: =+C63 -> 0 | D43: Dsp_FST | E43: 4511 | F43: =IF(E43>0,(VLOOKUP(E43,'Blnct AR'!$C$2:$D$2259,2,0))," ") -> Caixa Kwanza | G43: Eletricidade | I43: 5500
A44: =+A43 -> Eletricidade | C44: =+C43 -> 0 | D44: Dsp_FST | E44: 75212 | F44: =IF(E44>0,(VLOOKUP(E44,'Blnct AR'!$C$2:$D$2259,2,0))," ") -> Electricidade | G44: Eletricidade | H44: 5500
F45: =IF(E45>0,(VLOOKUP(E45,'Blnct AR'!$C$2:$D$2259,2,0))," ")
...

Sheet Diários
A1: Lançamentos | H1: =(SUM($H$2:$H$5345)-SUM($I$2:$I5346)) -> 0 | I1: =IF((SUM($I$2:$I$65928)-SUM($H$2:$H$65928))<>0,"DEB<>CRE","CONCLUÍDO") -> CONCLUÍDO
A2: 21 Caixa | C2: =+C128 -> 0 | D2: Pgto | E2: 4511 | F2: =IF(E2>0,(VLOOKUP(E2,'Blnct AR'!$C$2:$D$2259,2,0))," ") -> Caixa Kwanza | G2: Pgto Taxas | I2: 0
A3: =+A2 -> 21 Caixa | C3: =+C2 -> 0 | D3: =+D2 -> Pgto | E3: 75329 | F3: =IF(E3>0,(VLOOKUP(E3,'Blnct AR'!$C$2:$D$2259,2,0))," ") -> Outros impostos | G3: =+G2 -> Pgto Taxas | H3: =I2 -> 0
A5: 21 Caixa | C5: =+C131 -> 0 | D5: Rcbto | E5: 4511 | F5: =IF(E5>0,(VLOOKUP(E5,'Blnct AR'!$C$2:$D$2259,2,0))," ") -> Caixa Kwanza | G5: Rcbto Empréstimo | H5: 0
A6: =+A5 -> 21 Caixa | C6: =+C5 -> 0 | D6: =+D5 -> Rcbto | E6: 33921 | F6: =IF(E6>0,(VLOOKUP(E6,'Blnct AR'!$C$2:$D$2259,2,0))," ") -> Entidade grupo | G6: =+G5 -> Rcbto Empréstimo | I6: =H5 -> 0
A8: 21 Caixa | C8: =+C129 -> 0 | D8: INSS | E8: 4511 | F8: =IF(E8>0,(VLOOKUP(E8,'Blnct AR'!$C$2:$D$2259,2,0))," ") -> Caixa Kwanza | G8: Pgto INSS | I8: 0
A9: =+A8 -> 21 Caixa | C9: =+C8 -> 0 | D9: =+D8 -> INSS | E9: 3452 | F9: =IF(E9>0,(VLOOKUP(E9,'Blnct AR'!$C$2:$D$2259,2,0))," ") -> IVA - Dedutível | G9: =+G8 -> Pgto INSS | H9: =I8 -> 0
F10: =IF(E10>0,(VLOOKUP(E10,'Blnct AR'!$C$2:$D$2259,2,0))," ")
A11: 21 Caixa | C11: 0 | D11: IRT | E11: 4511 | F11: =IF(E11>0,(VLOOKUP(E11,'Blnct AR'!$C$2:$D$2259,2,0))," ") -> Caixa Kwanza | G11: Pgto IRT | I11: 0
A12: =+A11 -> 21 Caixa | C12: 0 | D12: =+D11 -> IRT | E12: 3431 | F12: =IF(E12>0,(VLOOKUP(E12,'Blnct AR'!$C$2:$D$2259,2,0))," ") -> IRT dependentes | G12: =+G11 -> Pgto IRT | H12: =I11 -> 0
F13: =IF(E13>0,(VLOOKUP(E13,'Blnct AR'!$C$2:$D$2259,2,0))," ")
A14: 21 Caixa | C14: 0 | D14: IPC | E14: 4511 | F14: =IF(E14>0,(VLOOKUP(E14,'Blnct AR'!$C$2:$D$2259,2,0))," ") -> Caixa Kwanza | G14: Pgto IPC | I14: 0
A15: =+A14 -> 21 Caixa | C15: 0 | D15: =+D14 -> IPC | E15: 75312 | F15: =IF(E15>0,(VLOOKUP(E15,'Blnct AR'!$C$2:$D$2259,2,0))," ") -> Imposto de Produção e Consumo | G15: =+G14 -> Pgto IPC | H15: =I14 -> 0
F16: =IF(E16>0,(VLOOKUP(E16,'Blnct AR'!$C$2:$D$2259,2,0))," ")
A17: 21 Caixa | C17: =+C48 -> 0 | D17: Imp_Selo | E17: 4511 | F17: =IF(E17>0,(VLOOKUP(E17,'Blnct AR'!$C$2:$D$2259,2,0))," ") -> Caixa Kwanza | G17: Pgto Imposto Selo | I17: 0
A18: =+A17 -> 21 Caixa | C18: =+C17 -> 0 | D18: =+D17 -> Imp_Selo | E18: 75311 | F18: =IF(E18>0,(VLOOKUP(E18,'Blnct AR'!$C$2:$D$2259,2,0))," ") -> Imposto de selo | G18: =+G17 -> Pgto Imposto Selo | H18: =+I17 -> 0
A20: 21 Caixa | C20: =+C50 -> 0 | D20: IsL 2% | E20: 4511 | F20: =IF(E20>0,(VLOOKUP(E20,'Blnct AR'!$C$2:$D$2259,2,0))," ") -> Caixa Kwanza | G20: Pgto IsL 2% | I20: 0
A21: =+A20 -> 21 Caixa | C21: =+C20 -> 0 | D21: =+D20 -> IsL 2% | E21: 3412 | F21: =IF(E21>0,(VLOOKUP(E21,'Blnct AR'!$C$2:$D$2259,2,0))," ") -> IL- pagamentos por conta | G21: =+G20 -> Pgto IsL 2% | H21: =+I20 -> 0
A23: 21 Caixa | C23: =+C50 -> 0 | D23: Rf_6,5% | E23: 4511 | F23: =IF(E23>0,(VLOOKUP(E23,'Blnct AR'!$C$2:$D$2259,2,0))," ") -> Caixa Kwanza | G23: Pgto Rf Fornecedor | I23: 0
A24: =+A23 -> 21 Caixa | C24: =+C23 -> 0 | D24: Dsp_FST | E24: 34131 | F24: =IF(E24>0,(VLOOKUP(E24,'Blnct AR'!$C$2:$D$2259,2,0))," ") -> Rf - juros bancarios | G24: =+G23 -> Pgto Rf Fornecedor | H24: =+I23 -> 0
A26: 31 Bancos | C26: =+C55 -> 0 | D26: Rcbto | E26: 43102 | F26: =IF(E26>0,(VLOOKUP(E26,'Blnct AR'!$C$2:$D$2259,2,0))," ") -> Banco - BECN. nº 0000984586 | G26: Recibo Cliente | H26: 0
A27: =+A26 -> 31 Bancos | C27: =+C26 -> 0 | D27: =+D26 -> Rcbto | E27: 31121008 | F27: =IF(E27>0,(VLOOKUP(E27,'Blnct AR'!$C$2:$D$2259,2,0))," ") -> Mota-Engil Angola,S.A | G27: =+G26 -> Recibo Cliente | I27: =+H26 -> 0
A29: 31 Bancos | C29: =+C58 -> 0 | D29: Dep_Num | E29: 43102 | F29: =IF(E29>0,(VLOOKUP(E29,'Blnct AR'!$C$2:$D$2259,2,0))," ") -> Banco - BECN. nº 0000984586 | G29: Depósito Numerário | H29: 0
A30: =+A29 -> 31 Bancos | C30: =+C29 -> 0 | D30: =+D29 -> Dep_Num | E30: 4511 | F30: =IF(E30>0,(VLOOKUP(E30,'Blnct AR'!$C$2:$D$2259,2,0))," ") -> Caixa Kwanza | G30: =+G29 -> Depósito Numerário | I30: =+H29 -> 0
A32: 31 Bancos | C32: =+C58 -> 0 | D32: Adtmto | E32: 43102 | F32: =IF(E32>0,(VLOOKUP(E32,'Blnct AR'!$C$2:$D$2259,2,0))," ") -> Banco - BECN. nº 0000984586 | G32: Adiantamento Cliente Cliente | H32: 0
A33: =+A32 -> 31 Bancos | C33: =+C32 -> 0 | D33: =+D32 -> Adtmto | E33: 319121001 | F33: =IF(E33>0,(VLOOKUP(E33,'Blnct AR'!$C$2:$D$2259,2,0))," ") -> Topoduarte Topografia e Imob, Lda | G33: =+G32 -> Adiantamento Cliente Cliente | I33: =+H32 -> 0
A35: 31 Bancos | C35: =+C34 -> 0 | D35: Dsp_Bnk | E35: 43102 | F35: =IF(E35>0,(VLOOKUP(E35,'Blnct AR'!$C$2:$D$2259,2,0))," ") -> Banco - BECN. nº 0000984586 | G35: Despesas Bancárias | I35: =SUM(H36:H38) -> 0
A36: =+A35 -> 31 Bancos | C36: =+C35 -> 0 | D36: =+D35 -> Dsp_Bnk | E36: 7673 | F36: =IF(E36>0,(VLOOKUP(E36,'Blnct AR'!$C$2:$D$2259,2,0))," ") -> Despesas Bancárias | G36: =+G35 -> Despesas Bancárias | H36: 0
A37: =+A36 -> 31 Bancos | C37: =+C36 -> 0 | D37: =+D36 -> Dsp_Bnk | E37: 7674 | F37: =IF(E37>0,(VLOOKUP(E37,'Blnct AR'!$C$2:$D$2259,2,0))," ") -> #N/A | G37: =+G36 -> Despesas Bancárias | H37: =H36*0.7% -> 0
A38: =+A37 -> 31 Bancos | C38: =+C37 -> 0 | D38: =+D37 -> Dsp_Bnk | E38: 7675 | F38: =IF(E38>0,(VLOOKUP(E38,'Blnct AR'!$C$2:$D$2259,2,0))," ") -> #N/A | G38: =+G37 -> Despesas Bancárias | H38: 0
F39: =IF(E39>0,(VLOOKUP(E39,'Blnct AR'!$C$2:$D$2259,2,0))," ")
A40: 31 Bancos | C40: =+C39 -> 0 | D40: Chq_Bnk | E40: 43102 | F40: =IF(E40>0,(VLOOKUP(E40,'Blnct AR'!$C$2:$D$2259,2,0))," ") -> Banco - BECN. nº 0000984586 | G40: Emissão Cheques | I40: =SUM(H41:H44) -> 0
A41: =+A40 -> 31 Bancos | C41: =+C40 -> 0 | D41: =+D40 -> Chq_Bnk | E41: 7671 | F41: =IF(E41>0,(VLOOKUP(E41,'Blnct AR'!$C$2:$D$2259,2,0))," ") -> Sb - livros bancarios | G41: =+G40 -> Emissão Cheques | H41: 0
A42: =+A41 -> 31 Bancos | C42: =+C41 -> 0 | D42: =+D41 -> Chq_Bnk | E42: 7674 | F42: =IF(E42>0,(VLOOKUP(E42,'Blnct AR'!$C$2:$D$2259,2,0))," ") -> #N/A | G42: =+G41 -> Emissão Cheques | H42: 0
A43: =+A42 -> 31 Bancos | C43: =+C42 -> 0 | D43: =+D42 -> Chq_Bnk | E43: 7674 | F43: =IF(E43>0,(VLOOKUP(E43,'Blnct AR'!$C$2:$D$2259,2,0))," ") -> #N/A | G43: =+G42 -> Emissão Cheques | H43: 0
A44: =+A42 -> 31 Bancos | C44: =+C42 -> 0 | D44: =+D42 -> Chq_Bnk | E44: 7675 | F44: =IF(E44>0,(VLOOKUP(E44,'Blnct AR'!$C$2:$D$2259,2,0))," ") -> #N/A | G44: =+G42 -> Emissão Cheques | H44: 0
A46: 31 Bancos | C46: =+C45 -> 0 | D46: Cms_Bnk | E46: 43105 | F46: =IF(E46>0,(VLOOKUP(E46,'Blnct AR'!$C$2:$D$2259,2,0))," ") -> Banco Valor- 00022736510001 | G46: Comissão | I46: =SUM(H47:H49) -> 2016
A47: =+A46 -> 31 Bancos | C47: =+C46 -> 0 | D47: =+D46 -> Cms_Bnk | E47: 7672 | F47: =IF(E47>0,(VLOOKUP(E47,'Blnct AR'!$C$2:$D$2259,2,0))," ") -> Sb - importação e exportação | G47: =+G46 -> Comissão | H47: 2000
A48: =+A47 -> 31 Bancos | C48: =+C47 -> 0 | D48: =+D47 -> Cms_Bnk | E48: 7674 | F48: =IF(E48>0,(VLOOKUP(E48,'Blnct AR'!$C$2:$D$2259,2,0))," ") -> #N/A | G48: =+G47 -> Comissão | H48: 14
A49: =+A48 -> 31 Bancos | C49: =+C48 -> 0 | D49: =+D48 -> Cms_Bnk | E49: 7675 | F49: =IF(E49>0,(VLOOKUP(E49,'Blnct AR'!$C$2:$D$2259,2,0))," ") -> #N/A | G49: =+G48 -> Comissão | H49: 2
...

Sheet Lanç
F1: =ROUND(SUM(F3:F3910)-SUM(G3:G3910),3) -> 0 | G1: =IF(F1<>0,"DEB<>CRE","CONCLUÍDO") -> CONCLUÍDO | H1: =Balanço!$I$52 -> 5.364418e-07
A2: DATA | B2: N.º | C2: CÓD. CONTA | D2: NOME DA CONTA | E2: DESCRITIVO | F2: DÉBITO | G2: CRÉDITO | H2: CRÉDITO
A3: 43830 | B3: ABE_20 | C3: 1122 | D3: =IF(C3>0,(VLOOKUP(C3,'Blnct AR'!$C$2:$D$2262,2,0))," ") -> Outras construções | E3: Abertura 2020 | F3: 33771041
A4: 43830 | B4: ABE_20 | C4: 1131 | D4: =IF(C4>0,(VLOOKUP(C4,'Blnct AR'!$C$2:$D$2262,2,0))," ") -> Material Industrial | E4: Abertura 2020 | F4: 8490739.8
A5: 43830 | B5: ABE_20 | C5: 1132 | D5: =IF(C5>0,(VLOOKUP(C5,'Blnct AR'!$C$2:$D$2262,2,0))," ") -> Ferramentas industriais | E5: Abertura 2020 | F5: 1582983.3
A6: 43830 | B6: ABE_20 | C6: 1134 | D6: =IF(C6>0,(VLOOKUP(C6,'Blnct AR'!$C$2:$D$2262,2,0))," ") -> Gerador Genalec | E6: Abertura 2020 | F6: 3481000
A7: 43830 | B7: ABE_20 | C7: 1135 | D7: =IF(C7>0,(VLOOKUP(C7,'Blnct AR'!$C$2:$D$2262,2,0))," ") -> Empilhadora | E7: Abertura 2020 | F7: 1916250
A8: 43830 | B8: ABE_20 | C8: 114201 | D8: =IF(C8>0,(VLOOKUP(C8,'Blnct AR'!$C$2:$D$2262,2,0))," ") -> Nissan Navara LD -07-66 DQ | E8: Abertura 2020 | F8: 3152500
A9: 43830 | B9: ABE_20 | C9: 114202 | D9: =IF(C9>0,(VLOOKUP(C9,'Blnct AR'!$C$2:$D$2262,2,0))," ") -> Suzuki Grand Vitara LD-05-65-EF | E9: Abertura 2020 | F9: 4455000
A10: 43830 | B10: ABE_20 | C10: 114203 | D10: =IF(C10>0,(VLOOKUP(C10,'Blnct AR'!$C$2:$D$2262,2,0))," ") -> Nissan Micra LD-95-52-FZ | E10: Abertura 2020 | F10: 2500000
A11: 43830 | B11: ABE_20 | C11: 114205 | D11: =IF(C11>0,(VLOOKUP(C11,'Blnct AR'!$C$2:$D$2262,2,0))," ") -> SSANGYON Rexton RX LD-28-34-GD | E11: Abertura 2020 | F11: 4400000
A12: 43830 | B12: ABE_20 | C12: 114207 | D12: =IF(C12>0,(VLOOKUP(C12,'Blnct AR'!$C$2:$D$2262,2,0))," ") -> JMC Conquer 3360 LD-88-46-GK | E12: Abertura 2020 | F12: 3165000
A13: 43830 | B13: ABE_20 | C13: 114208 | D13: =IF(C13>0,(VLOOKUP(C13,'Blnct AR'!$C$2:$D$2262,2,0))," ") -> Motorizada | E13: Abertura 2020 | F13: 269000
A14: 43830 | B14: ABE_20 | C14: 114209 | D14: =IF(C14>0,(VLOOKUP(C14,'Blnct AR'!$C$2:$D$2262,2,0))," ") -> Ford Ranger - LD-22-37-FS | E14: Abertura 2020 | F14: 12400000
... A23: 43830 | B23: ABE_20 | C23: 1291 | D23: =IF(C23>0,(VLOOKUP(C23,'Blnct AR'!$C$2:$D$2262,2,0))," ") -> Outras imobilizações incorporeas | E23: Abertura 2020 | F23: 1717400
A24: 43830 | B24: ABE_20 | C24: 1812 | D24: =IF(C24>0,(VLOOKUP(C24,'Blnct AR'!$C$2:$D$2262,2,0))," ") -> Edificios e outras construções | E24: Abertura 2020 | F24: =IF(G24+H24<>0,G24-H24,"") -> -23837407 | H24: 23837407
A25: 43830 | B25: ABE_20 | C25: 1813 | D25: =IF(C25>0,(VLOOKUP(C25,'Blnct AR'!$C$2:$D$2262,2,0))," ") -> Equipamento básico | E25: Abertura 2020 | F25: =IF(G25+H25<>0,G25-H25,"") -> -7966128.4 | H25: 7966128.4
A26: 43830 | B26: ABE_20 | C26: 18141 | D26: =IF(C26>0,(VLOOKUP(C26,'Blnct AR'!$C$2:$D$2262,2,0))," ") -> Equipamento de carga e transporte | E26: Abertura 2020 | F26: =IF(G26+H26<>0,G26-H26,"") -> -26408167 | H26: 26408167
A27: 43830 | B27: ABE_20 | C27: 18151 | D27: =IF(C27>0,(VLOOKUP(C27,'Blnct AR'!$C$2:$D$2262,2,0))," ") -> Equipamento administrativo | E27: Abertura 2020 | F27: =IF(G27+H27<>0,G27-H27,"") -> -4654722.3 | H27: 4654722.3
A28: 43830 | B28: ABE_20 | C28: 1819 | D28: =IF(C28>0,(VLOOKUP(C28,'Blnct AR'!$C$2:$D$2262,2,0))," ") -> Outras imobilizações corpóreas | E28: Abertura 2020 | F28: =IF(G28+H28<>0,G28-H28,"") -> -86451 | H28: 86451
A29: 43830 | B29: ABE_20 | C29: 1829 | D29: =IF(C29>0,(VLOOKUP(C29,'Blnct AR'!$C$2:$D$2262,2,0))," ") -> Outras imobilizações incorporeas | E29: Abertura 2020 | F29: =IF(G29+H29<>0,G29-H29,"") -> -5669341.6 | H29: 5669341.6
A30: 43830 | B30: ABE_20 | C30: 211111 | D30: =IF(C30>0,(VLOOKUP(C30,'Blnct AR'!$C$2:$D$2262,2,0))," ") -> Mp.MN-Custo de factura | E30: Abertura 2020 | F30: 1566614
A31: 43830 | B31: ABE_20 | C31: 2211 | D31: =IF(C31>0,(VLOOKUP(C31,'Blnct AR'!$C$2:$D$2262,2,0))," ") -> Mp-Existências | E31: Abertura 2020 | F31: 27786231
A32: 43830 | B32: ABE_20 | C32: 2713 | D32: =IF(C32>0,(VLOOKUP(C32,'Blnct AR'!$C$2:$D$2262,2,0))," ") -> Mp.-Outros Mercados | E32: Abertura 2020 | F32: 11330087
A33: 43830 | B33: ABE_20 | C33: 31121003 | D33: =IF(C33>0,(VLOOKUP(C33,'Blnct AR'!$C$2:$D$2262,2,0))," ") -> UEM-Unid. Estruturas Metálicas, SA | E33: Abertura 2020 | F33: 27891307
A34: 43830 | B34: ABE_20 | C34: 31121009 | D34: =IF(C34>0,(VLOOKUP(C34,'Blnct AR'!$C$2:$D$2262,2,0))," ") -> Matra Engenharia e Construção, Lda | E34: Abertura 2020 | F34: 16613407
A35: 43830 | B35: ABE_20 | C35: 31121035 | D35: =IF(C35>0,(VLOOKUP(C35,'Blnct AR'!$C$2:$D$2262,2,0))," ") -> Cummins Angola, Lda | E35: Abertura 2020 | F35: 878.9
A36: 43830 | B36: ABE_20 | C36: 31121051 | D36: =IF(C36>0,(VLOOKUP(C36,'Blnct AR'!$C$2:$D$2262,2,0))," ") -> LYON- Contrução e Manut.Met. | E36: Abertura 2020 | F36: =IF(G36+H36<>0,G36-H36,"") -> -500000 | H36: 500000
A37: 43830 | B37: ABE_20 | C37: 31121077 | D37: =IF(C37>0,(VLOOKUP(C37,'Blnct AR'!$C$2:$D$2262,2,0))," ") -> CATOCA - Sociedade Mineira de Catoca, Lda | E37: Abertura 2020 | F37: 1520238.9
A38: 43830 | B38: ABE_20 | C38: 31121117 | D38: =IF(C38>0,(VLOOKUP(C38,'Blnct AR'!$C$2:$D$2262,2,0))," ") -> PSI Angola | E38: Abertura 2020 | F38: =IF(G38+H38<>0,G38-H38,"") -> -0.9 | H38: 0.9
A39: 43830 | B39: ABE_20 | C39: 31121118 | D39: =IF(C39>0,(VLOOKUP(C39,'Blnct AR'!$C$2:$D$2262,2,0))," ") -> Cimaleste | E39: Abertura 2020 | F39: 2205500
A40: 43830 | B40: ABE_20 | C40: 31121114 | D40: =IF(C40>0,(VLOOKUP(C40,'Blnct AR'!$C$2:$D$2262,2,0))," ") -> SEDIAC-Soc. de Est., Desenv. Ind. Agrícola e Corm. SA | E40: Abertura 2020 | F40: 202910.42
A41: 43830 | B41: ABE_20 | C41: 31121116 | D41: =IF(C41>0,(VLOOKUP(C41,'Blnct AR'!$C$2:$D$2262,2,0))," ") -> IMAVIZ - MINING, LDA. | E41: Abertura 2020 | F41: 2529830.5
A42: 43830 | B42: ABE_20 | C42: 3171034 | D42: =IF(C42>0,(VLOOKUP(C42,'Blnct AR'!$C$2:$D$2262,2,0))," ") -> Cummins Angola, Lda | E42: Abertura 2020 | F42: 94311.1
A43: 43830 | B43: ABE_20 | C43: 3171077 | D43: =IF(C43>0,(VLOOKUP(C43,'Blnct AR'!$C$2:$D$2262,2,0))," ") -> CATOCA - Sociedade Mineira de Catoca, Lda | E43: Abertura 2020 | F43: 10310385
A44: 43830 | B44: ABE_20 | C44: 3171113 | D44: =IF(C44>0,(VLOOKUP(C44,'Blnct AR'!$C$2:$D$2262,2,0))," ") -> PSI Angola | E44: Abertura 2020 | F44: 19500
A45: 43830 | B45: ABE_20 | C45: 3171114 | D45: =IF(C45>0,(VLOOKUP(C45,'Blnct AR'!$C$2:$D$2262,2,0))," ") -> Cimaleste | E45: Abertura 2020 | F45: 19500
A46: 43830 | B46: ABE_20 | C46: 3171116 | D46: =IF(C46>0,(VLOOKUP(C46,'Blnct AR'!$C$2:$D$2262,2,0))," ") -> IMAVIZ - MINING, LDA. | E46: Abertura 2020 | F46: 196167.61
A47: 43830 | B47: ABE_20 | C47: 318121 | D47: =IF(C47>0,(VLOOKUP(C47,'Blnct AR'!$C$2:$D$2262,2,0))," ") -> Nacionais | E47: Abertura 2020 | F47: 32608955
A48: 43831 | B48: ABE_20 | C48: 318121100 | D48: =IF(C48>0,(VLOOKUP(C48,'Blnct AR'!$C$2:$D$2262,2,0))," ") -> Motortech serviços | E48: Abertura 2021 | F48: 3400000
...

Sheet Blnct AR
C2: BALANCETE ANALÍTICO APURAMENTO RESULTADOS
E3: =SUBTOTAL(9,E5:E2262) -> -3.0757746e+08 | F3: =SUBTOTAL(9,F5:F2262) -> 7.1894976e+09 | G3: =SUBTOTAL(9,G5:G2262) -> 7.0853258e+09 | H3: =SUBTOTAL(9,H5:H2262) -> 1.0417181e+08 | I3: =SUBTOTAL(9,I5:I2262) -> -2.0340564e+08 | S3: =F3-G3 -> 1.0417181e+08
A4: CRL 0,00 | B4: TIPO | C4: CÓDIGO | D4: DESCRICAO | E4: SALDO ANTERIOR | F4: DÉBITO PERIODO | G4: CRÉDITO PERIODO | H4: SALDO PERIODO | I4: SALDO ACUMULADO
A5: =IF(E5+F5+G5+H5+I5=0,1,0) -> 0 | B5: CL | C5: 1 | D5: MEIOS FIXOS E INVESTIMENTOS | E5: =SUM(E6,E58,E70,E91,E102,E128) -> 24061604 | F5: =SUM(F6,F58,F70,F91,F102,F128) -> 15239773 | G5: =SUM(G6,G58,G70,G91,G102,G128) -> 0 | H5: =(F5)-(G5) -> 15239773 | I5: =(E5)+(H5) -> 39301377
A6: =IF(E6+F6+G6+H6+I6=0,1,0) -> 0 | B6: R | C6: 11 | D6: IMOBILIZAÇÕES CORPÓREAS | E6: =SUM(E7,E15,E23,E31,E44,E52,E55) -> 86785921 | F6: =SUM(F7,F11,F15,F23,F31,F44,F52,F55) -> 15239773 | G6: =SUM(G23,G31,G44,G52,G55) -> 0 | H6: =(F6)-(G6) -> 15239773 | I6: =(E6)+(H6) -> 1.0202569e+08
A7: =IF(E7+F7+G7+H7+I7=0,1,0) -> 1 | B7: I | C7: 111 | D7: Terrenos e Recursos Naturais | E7: =SUM(E8:E10,E11) -> 0 | F7: =SUM(F8:F10,F11) -> 0 | G7: =SUM(G8:G10,G11) -> 0 | H7: =(F7)-(G7) -> 0 | I7: =(E7)+(H7) -> 0
A8: =IF(E8+F8+G8+H8+I8=0,1,0) -> 1 | B8: M | C8: 1111 | D8: Terrenos em Bruto | E8: =SUM(E9:E10) -> 0 | F8: =SUMIF(Lanç!$C$115:$C$6504,C8,Lanç!$F$115:$F$6504) -> 0 | G8: =SUMIF(Lanç!$C$115:$C$6504,C8,Lanç!$G$115:$G$6504) -> 0 | H8: =(F8)-(G8) -> 0 | I8: =(E8)+(H8) -> 0
A9: =IF(E9+F9+G9+H9+I9=0,1,0) -> 1 | B9: M | C9: 1112 | D9: Terrenos com Arranjos | E9: =SUMIF(Lanç!$C$3:$C$114,C9,Lanç!$F$3:$F$114) -> 0 | F9: =SUMIF(Lanç!$C$115:$C$6504,C9,Lanç!$F$115:$F$6504) -> 0 | G9: =SUMIF(Lanç!$C$115:$C$6504,C9,Lanç!$G$115:$G$6504) -> 0 | H9: =(F9)-(G9) -> 0 | I9: =(E9)+(H9) -> 0
A10: =IF(E10+F10+G10+H10+I10=0,1,0) -> 1 | B10: M | C10: 1113 | D10: Subsolos | E10: =SUMIF(Lanç!$C$3:$C$114,C10,Lanç!$F$3:$F$114) -> 0 | F10: =SUMIF(Lanç!$C$115:$C$6504,C10,Lanç!$F$115:$F$6504) -> 0 | G10: =SUMIF(Lanç!$C$115:$C$6504,C10,Lanç!$G$115:$G$6504) -> 0 | H10: =(F10)-(G10) -> 0 | I10: =(E10)+(H10) -> 0
A11: =IF(E11+F11+G11+H11+I11=0,1,0) -> 1 | B11: I | C11: 1114 | D11: Terrenos com edificios | E11: =SUM(E12:E14) -> 0 | F11: =SUM(F12:F14) -> 0 | G11: =SUM(G12:G14) -> 0 | H11: =(F11)-(G11) -> 0 | I11: =(E11)+(H11) -> 0
A12: =IF(E12+F12+G12+H12+I12=0,1,0) -> 1 | B12: M | C12: 11141 | D12: Relativos edificios industriais | E12: =SUMIF(Lanç!$C$3:$C$114,C12,Lanç!$F$3:$F$114) -> 0 | F12: =SUMIF(Lanç!$C$115:$C$6504,C12,Lanç!$F$115:$F$6504) -> 0 | G12: =SUMIF(Lanç!$C$115:$C$6504,C12,Lanç!$G$115:$G$6504) -> 0 | H12: =(F12)-(G12) -> 0 | I12: =(E12)+(H12) -> 0
A13: =IF(E13+F13+G13+H13+I13=0,1,0) -> 1 | B13: M | C13: 11142 | D13: Relativos edi. administrativos/come | E13: =SUMIF(Lanç!$C$3:$C$114,C13,Lanç!$F$3:$F$114) -> 0 | F13: =SUMIF(Lanç!$C$115:$C$6504,C13,Lanç!$F$115:$F$6504) -> 0 | G13: =SUMIF(Lanç!$C$115:$C$6504,C13,Lanç!$G$115:$G$6504) -> 0 | H13: =(F13)-(G13) -> 0 | I13: =(E13)+(H13) -> 0
A14: =IF(E14+F14+G14+H14+I14=0,1,0) -> 1 | B14: M | C14: 11143 | D14: Relativos a outros edificios | E14: =SUMIF(Lanç!$C$3:$C$114,C14,Lanç!$F$3:$F$114) -> 0 | F14: =SUMIF(Lanç!$C$115:$C$6504,C14,Lanç!$F$115:$F$6504) -> 0 | G14: =SUMIF(Lanç!$C$115:$C$6504,C14,Lanç!$G$115:$G$6504) -> 0 | H14: =(F14)-(G14) -> 0 | I14: =(E14)+(H14) -> 0
A15: =IF(E15+F15+G15+H15+I15=0,1,0) -> 0 | B15: I | C15: 112 | D15: Edificios e outras Construções | E15: =SUM(E16:E21) -> 33771041 | F15: =SUM(F16:F21) -> 0 | G15: =SUM(G16:G21) -> 0 | H15: =(F15)-(G15) -> 0 | I15: =(E15)+(H15) -> 33771041
A16: =IF(E16+F16+G16+H16+I16=0,1,0) -> 1 | B16: M | C16: 1121 | D16: Edificios | E16: =SUMIF(Lanç!$C$3:$C$114,C16,Lanç!$F$3:$F$114) -> 0 | F16: =SUMIF(Lanç!$C$115:$C$6504,C16,Lanç!$F$115:$F$6504) -> 0 | G16: =SUMIF(Lanç!$C$115:$C$6504,C16,Lanç!$G$115:$G$6504) -> 0 | H16: =(F16)-(G16) -> 0 | I16: =(E16)+(H16) -> 0
A17: =IF(E17+F17+G17+H17+I17=0,1,0) -> 1 | B17: M | C17: 11211 | D17: Integrados em conjuntos industriais | E17: =SUMIF(Lanç!$C$3:$C$114,C17,Lanç!$F$3:$F$114) -> 0 | F17: =SUMIF(Lanç!$C$115:$C$6504,C17,Lanç!$F$115:$F$6504) -> 0 | G17: =SUMIF(Lanç!$C$115:$C$6504,C17,Lanç!$G$115:$G$6504) -> 0 | H17: =(F17)-(G17) -> 0 | I17: =(E17)+(H17) -> 0
A18: =IF(E18+F18+G18+H18+I18=0,1,0) -> 1 | B18: M | C18: 11212 | D18: Integrados em conj.adm.e comerciais | E18: =SUMIF(Lanç!$C$3:$C$114,C18,Lanç!$F$3:$F$114) -> 0 | F18: =SUMIF(Lanç!$C$115:$C$6504,C18,Lanç!$F$115:$F$6504) -> 0 | G18: =SUMIF(Lanç!$C$115:$C$6504,C18,Lanç!$G$115:$G$6504) -> 0 | H18: =(F18)-(G18) -> 0 | I18: =(E18)+(H18) -> 0
A19: =IF(E19+F19+G19+H19+I19=0,1,0) -> 1 | B19: M | C19: 11213 | D19: Outros conjuntos industriais | E19: =SUMIF(Lanç!$C$3:$C$114,C19,Lanç!$F$3:$F$114) -> 0 | F19: =SUMIF(Lanç!$C$115:$C$6504,C19,Lanç!$F$115:$F$6504) -> 0 | G19: =SUMIF(Lanç!$C$115:$C$6504,C19,Lanç!$G$115:$G$6504) -> 0 | H19: =(F19)-(G19) -> 0 | I19: =(E19)+(H19) -> 0
A20: =IF(E20+F20+G20+H20+I20=0,1,0) -> 1 | B20: M | C20: 11214 | D20: Implantados em propriedade alheia | E20: =SUMIF(Lanç!$C$3:$C$114,C20,Lanç!$F$3:$F$114) -> 0 | F20: =SUMIF(Lanç!$C$115:$C$6504,C20,Lanç!$F$115:$F$6504) -> 0 | G20: =SUMIF(Lanç!$C$115:$C$6504,C20,Lanç!$G$115:$G$6504) -> 0 | H20: =(F20)-(G20) -> 0 | I20: =(E20)+(H20) -> 0
A21: =IF(E21+F21+G21+H21+I21=0,1,0) -> 0 | B21: M | C21: 1122 | D21: Outras construções | E21: =SUMIF(Lanç!C3:C114,C21,Lanç!F3:F114) -> 33771041 | F21: =SUMIF(Lanç!C115:C6504,C21,Lanç!F115:F6504) -> 0 | G21: =SUMIF(Lanç!C115:C6504,C21,Lanç!G115:G6504) -> 0 | H21: =(F21)-(G21) -> 0 | I21: =(E21)+(H21) -> 33771041
A22: =IF(E22+F22+G22+H22+I22=0,1,0) -> 1 | B22: M | C22: 1123 | D22: Instalações posto transformador | E22: =SUMIF(Lanç!$C$3:$C$114,C22,Lanç!$F$3:$F$114) -> 0 | F22: =SUMIF(Lanç!$C$115:$C$6504,C22,Lanç!$F$115:$F$6504) -> 0 | G22: =SUMIF(Lanç!$C$115:$C$6504,C22,Lanç!$G$115:$G$6504) -> 0 | H22: =(F22)-(G22) -> 0 | I22: =(E22)+(H22) -> 0
A23: =IF(E23+F23+G23+H23+I23=0,1,0) -> 0 | B23: I | C23: 113 | D23: Equipamento básico | E23: =SUM(E24) -> 15470973 | F23: =SUM(F24) -> 1200000 | G23: =SUM(G24) -> 0 | H23: =(F23)-(G23) -> 1200000 | I23: =(E23)+(H23) -> 16670973
A24: =IF(E24+F24+G24+H24+I24=0,1,0) -> 0 | B24: I | C24: 1131 | D24: Material Industrial | E24: =SUM(E25:E30) -> 15470973 | F24: =SUM(F25:F30) -> 1200000 | G24: =SUM(G25:G30) -> 0 | H24: =(F24)-(G24) -> 1200000 | I24: =(E24)+(H24) -> 16670973
A25: =IF(E25+F25+G25+H25+I25=0,1,0) -> 0 | B25: M | C25: 1131 | D25: Contentor Marítimo | E25: =SUMIF(Lanç!C3:C114,C25,Lanç!F3:F114) -> 8490739.8 | F25: =SUMIF(Lanç!C115:C6504,C25,Lanç!F115:F6504) -> 0 | G25: =SUMIF(Lanç!C115:C6504,C25,Lanç!G115:G6504) -> 0 | H25: =(F25)-(G25) -> 0 | I25: =(E25)+(H25) -> 8490739.8
A26: =IF(E26+F26+G26+H26+I26=0,1,0) -> 0 | B26: M | C26: 1132 | D26: Ferramentas industriais | E26: =SUMIF(Lanç!C3:C114,C26,Lanç!F3:F114) -> 1582983.3 | F26: =SUMIF(Lanç!C115:C6504,C26,Lanç!F115:F6504) -> 0 | G26: =SUMIF(Lanç!C115:C6504,C26,Lanç!G115:G6504) -> 0 | H26: =(F26)-(G26) -> 0 | I26: =(E26)+(H26) -> 1582983.3
A27: =IF(E27+F27+G27+H27+I27=0,1,0) -> 1 | B27: M | C27: 1133 | D27: Melhoramentos em equip.básicos | E27: =SUMIF(Lanç!$C$3:$C$114,C27,Lanç!$F$3:$F$114) -> 0 | F27: =SUMIF(Lanç!$C$115:$C$6504,C27,Lanç!$F$115:$F$6504) -> 0 | G27: =SUMIF(Lanç!$C$115:$C$6504,C27,Lanç!$G$115:$G$6504) -> 0 | H27: =(F27)-(G27) -> 0 | I27: =(E27)+(H27) -> 0
A28: =IF(E28+F28+G28+H28+I28=0,1,0) -> 0 | B28: M | C28: 1134 | D28: Gerador Genalec | E28: =SUMIF(Lanç!C3:C114,C28,Lanç!F3:F114) -> 3481000 | F28: =SUMIF(Lanç!C115:C6504,C28,Lanç!F115:F6504) -> 0 | G28: =SUMIF(Lanç!C115:C6504,C28,Lanç!G115:G6504) -> 0 | H28: =(F28)-(G28) -> 0 | I28: =(E28)+(H28) -> 3481000
A29: =IF(E29+F29+G29+H29+I29=0,1,0) -> 0 | B29: M | C29: 1135 | D29: Empilhadora | E29: =SUMIF(Lanç!C2:C113,C29,Lanç!F2:F113) -> 1916250 | F29: =SUMIF(Lanç!C114:C6503,C29,Lanç!F114:F6503) -> 0 | G29: =SUMIF(Lanç!C114:C6503,C29,Lanç!G114:G6503) -> 0 | H29: =(F29)-(G29) -> 0 | I29: =(E29)+(H29) -> 1916250
A30: =IF(E30+F30+G30+H30+I30=0,1,0) -> 0 | B30: M | C30: 1136 | D30: Gerador Kipor | E30: =SUMIF(Lanç!C3:C114,C30,Lanç!F3:F114) -> 0 | F30: =SUMIF(Lanç!C115:C6504,C30,Lanç!F115:F6504) -> 1200000 | G30: =SUMIF(Lanç!C115:C6504,C30,Lanç!G115:G6504) -> 0 | H30: =(F30)-(G30) -> 1200000 | I30: =(E30)+(H30) -> 1200000
A31: =IF(E31+F31+G31+H31+I31=0,1,0) -> 0 | B31: I | C31: 114 | D31: Equipamento de carga e transporte | E31: =SUM(E32,E33) -> 30341500 | F31: =SUM(F32,F33) -> 13611616 | G31: =SUM(G32,G33) -> 0 | H31: =(F31)-(G31) -> 13611616 | I31: =(E31)+(H31) -> 43953116
A32: =IF(E32+F32+G32+H32+I32=0,1,0) -> 1 | B32: M | C32: 1141 | D32: Veiculos pesados | E32: =SUMIF(Lanç!$C$3:$C$114,C32,Lanç!$F$3:$F$114) -> 0 | F32: =SUMIF(Lanç!$C$115:$C$6504,C32,Lanç!$F$115:$F$6504) -> 0 | G32: =SUMIF(Lanç!$C$115:$C$6504,C32,Lanç!$G$115:$G$6504) -> 0 | H32: =(F32)-(G32) -> 0 | I32: =(E32)+(H32) -> 0
A33: =IF(E33+F33+G33+H33+I33=0,1,0) -> 0 | B33: I | C33: 1142 | D33: Veiculos mistos e ligeiros | E33: =SUM(E34:E43) -> 30341500 | F33: =SUM(F34:F43) -> 13611616 | G33: =SUM(G34:G43) -> 0 | H33: =(F33)-(G33) -> 13611616 | I33: =(E33)+(H33) -> 43953116
A34: =IF(E34+F34+G34+H34+I34=0,1,0) -> 0 | B34: M | C34: 114201 | D34: Nissan Navara LD -07-66 DQ | E34: =SUMIF(Lanç!C3:C114,C34,Lanç!F3:F114) -> 3152500 | F34: =SUMIF(Lanç!C115:C6504,C34,Lanç!F115:F6504) -> 0 | G34: =SUMIF(Lanç!C115:C6504,C34,Lanç!G115:G6504) -> 0 | H34: =(F34)-(G34) -> 0 | I34: =(E34)+(H34) -> 3152500
A35: =IF(E35+F35+G35+H35+I35=0,1,0) -> 0 | B35: M | C35: 114202 | D35: Suzuki Grand Vitara LD-05-65-EF | E35: =SUMIF(Lanç!C3:C114,C35,Lanç!F3:F114) -> 4455000 | F35: =SUMIF(Lanç!C115:C6504,C35,Lanç!F115:F6504) -> 0 | G35: =SUMIF(Lanç!C115:C6504,C35,Lanç!G115:G6504) -> 0 | H35: =(F35)-(G35) -> 0 | I35: =(E35)+(H35) -> 4455000
A36: =IF(E36+F36+G36+H36+I36=0,1,0) -> 0 | B36: M | C36: 114203 | D36: Nissan Micra LD-95-52-FZ | E36: =SUMIF(Lanç!C3:C114,C36,Lanç!F3:F114) -> 2500000 | F36: =SUMIF(Lanç!C115:C6504,C36,Lanç!F115:F6504) -> 0 | G36: =SUMIF(Lanç!C115:C6504,C36,Lanç!G115:G6504) -> 0 | H36: =(F36)-(G36) -> 0 | I36: =(E36)+(H36) -> 2500000
A37: =IF(E37+F37+G37+H37+I37=0,1,0) -> 1 | B37: M | C37: 114204 | D37: Plataforma Articulado Piego 1985x750 | E37: =SUMIF(Lanç!$C$3:$C$114,C37,Lanç!$F$3:$F$114) -> 0 | F37: =SUMIF(Lanç!$C$115:$C$6504,C37,Lanç!$F$115:$F$6504) -> 0 | G37: =SUMIF(Lanç!$C$115:$C$6504,C37,Lanç!$G$115:$G$6504) -> 0 | H37: =(F37)-(G37) -> 0 | I37: =(E37)+(H37) -> 0
A38: =IF(E38+F38+G38+H38+I38=0,1,0) -> 0 | B38: M | C38: 114205 | D38: SSANGYON Rexton RX LD-28-34-GD | E38: =SUMIF(Lanç!C3:C114,C38,Lanç!F3:F114) -> 4400000 | F38: =SUMIF(Lanç!C115:C6504,C38,Lanç!F115:F6504) -> 0 | G38: =SUMIF(Lanç!C115:C6504,C38,Lanç!G115:G6504) -> 0 | H38: =(F38)-(G38) -> 0 | I38: =(E38)+(H38) -> 4400000
A39: =IF(E39+F39+G39+H39+I39=0,1,0) -> 1 | B39: M | C39: 114206 | D39: Nissan Micra HB 4AT | E39: =SUMIF(Lanç!C3:C114,C39,Lanç!F3:F114) -> 0 | F39: =SUMIF(Lanç!C115:C6504,C39,Lanç!F115:F6504) -> 0 | G39: =SUMIF(Lanç!C115:C6504,C39,Lanç!G115:G6504) -> 0 | H39: =(F39)-(G39) -> 0 | I39: =(E39)+(H39) -> 0
A40: =IF(E40+F40+G40+H40+I40=0,1,0) -> 0 | B40: M | C40: 114207 | D40: JMC Conquer 3360 LD-88-46-GK | E40: =SUMIF(Lanç!C3:C114,C40,Lanç!F3:F114) -> 3165000 | F40: =SUMIF(Lanç!C115:C6504,C40,Lanç!F115:F6504) -> 0 | G40: =SUMIF(Lanç!C115:C6504,C40,Lanç!G115:G6504) -> 0 | H40: =(F40)-(G40) -> 0 | I40: =(E40)+(H40) -> 3165000
A41: =IF(E41+F41+G41+H41+I41=0,1,0) -> 0 | B41: M | C41: 114208 | D41: Motorizada | E41: =SUMIF(Lanç!C3:C114,C41,Lanç!F3:F114) -> 269000 | F41: =SUMIF(Lanç!C115:C6504,C41,Lanç!F115:F6504) -> 0 | G41: =SUMIF(Lanç!C115:C6504,C41,Lanç!G115:G6504) -> 0 | H41: =(F41)-(G41) -> 0 | I41: =(E41)+(H41) -> 269000
...

Sheet Balanço
G1: =DBase!C6 -> Mbolo Yeto
B3: =DBase!B15 -> BALANÇO EM
B4: =DBase!F15 -> 46022
G6: Valores expressos em AKZ
B7: Designção | E7: Notas | F7: Exercicios
F8: =DBase!C4 -> 45658 | G8: =F8-1 -> 45657
B9: ACTIVO
B10: Activos não Correntes
B11: Imobilizações corpóreas | E11: 4 | F11: ='Blnct AR'!I6 -> 1.0202569e+08 | G11: ='Blnct AR'!E6 -> 86785921
B12: Imobilizações incorpóreas | E12: 5 | F12: ='Blnct AR'!I58 -> 5897900 | G12: ='Blnct AR'!E58 -> 5897900
B13: Amortizações Acumuladas | F13: ='Blnct AR'!I102 -> -68622217 | G13: ='Blnct AR'!E102 -> -68622217
B14: Outros activos não correntes | E14: 7 | F14: 0 | G14: 0
D15: Total dos Activos Não Correntes | F15: =SUM(F11:F14) -> 39301377 | G15: =SUM(G11:G14) -> 24061604
B17: Activos Correntes
B18: Existências | E18: 8 | F18: ='Blnct AR'!I147 -> 81037969 | G18: ='Blnct AR'!E147 -> 40682932
B19: Contas a Receber | E19: 9 | F19: =IF('Blnct AR'!I388>0,'Blnct AR'!I388,0)+IF('Blnct AR'!I1036>0,'Blnct AR'!I1036,0)+IF('Blnct AR'!I1135>0,'Blnct AR'!I1135,0)+IF('Blnct AR'!I1181>0,'Blnct AR'!I1181,0)+IF('Blnct AR'!I1419<0,'Blnct AR'!I1419,0) -> 2.1787692e+08 | G19: =IF('Blnct AR'!E388>0,'Blnct AR'!E388,0)+IF('Blnct AR'!E1036>0,'Blnct AR'!E1036,0)+IF('Blnct AR'!E1135>0,'Blnct AR'!E1135,0)+IF('Blnct AR'!E1181>0,'Blnct AR'!E1181,0)+IF('Blnct AR'!E1419<0,'Blnct AR'!E1419,0) -> 1.1135149e+08
B20: Disponibilidades | E20: 10 | F20: ='Blnct AR'!I1453 -> 30063528 | G20: ='Blnct AR'!E1453 -> 99141178
B21: Outros Acivos Correntes | E21: 11 | F21: =+(IF('Blnct AR'!I1245>0,'Blnct AR'!E1245,0)+(IF('Blnct AR'!I1267>0,'Blnct AR'!I1267,0)+(IF('Blnct AR'!I1280>0,'Blnct AR'!I1280,0)+IF('Blnct AR'!I1284>0,'Blnct AR'!I1284,0))+IF('Blnct AR'!I1294>0,'Blnct AR'!I1294,0)+IF('Blnct AR'!I1302>0,'Blnct AR'!I1302,0)+IF('Blnct AR'!I1309>0,'Blnct AR'!I1309,0)+IF('Blnct AR'!I1311>0,'Blnct AR'!I1311,0)+IF('Blnct AR'!I1321>0,'Blnct AR'!I1321,0))) -> 0 | G21: =+(IF('Blnct AR'!E1245>0,'Blnct AR'!E1245,0)+(IF('Blnct AR'!E1267>0,'Blnct AR'!E1267,0)+(IF('Blnct AR'!E1280>0,'Blnct AR'!E1280,0)+IF('Blnct AR'!E1284>0,'Blnct AR'!E1284,0))+IF('Blnct AR'!E1294>0,'Blnct AR'!E1294,0)+IF('Blnct AR'!E1302>0,'Blnct AR'!E1302,0)+IF('Blnct AR'!E1309>0,'Blnct AR'!E1309,0)+IF('Blnct AR'!E1311>0,'Blnct AR'!E1311,0)+IF('Blnct AR'!E1321>0,'Blnct AR'!E1321,0))) -> 0
D22: Total dos Activos Correntes | F22: =SUM(F18:F21) -> 3.2897842e+08 | G22: =SUM(G18:G21) -> 2.511756e+08
B24: TOTAL DO ACTIVO | F24: =F15+F22 -> 3.682798e+08 | G24: =G15+G22 -> 2.7523721e+08
B25: CAPITAL PRÓPRIO E PASSIVO
B27: Capital Próprio
B28: Capital | E28: 12 | F28: =-'Blnct AR'!I1539-'Blnct AR'!I1552 -> 17532640 | G28: =-'Blnct AR'!E1539-'Blnct AR'!E1552 -> 17532640
B29: Reservas | E29: 13 | F29: =-(IF('Blnct AR'!I1555<>0,'Blnct AR'!I1555,0)+IF('Blnct AR'!I1557<>0,'Blnct AR'!I1557,0)+IF('Blnct AR'!I1561<>0,'Blnct AR'!I1561,0)+IF('Blnct AR'!I1564<>0,'Blnct AR'!I1564,0)+IF('Blnct AR'!I1567<>0,'Blnct AR'!I1567,0)) -> 1309804.4 | G29: =-(IF('Blnct AR'!E1555<>0,'Blnct AR'!E1555,0)+IF('Blnct AR'!E1557<>0,'Blnct AR'!E1557,0)+IF('Blnct AR'!E1561<>0,'Blnct AR'!E1561,0)+IF('Blnct AR'!E1564<>0,'Blnct AR'!E1564,0)+IF('Blnct AR'!E1567<>0,'Blnct AR'!E1567,0)) -> 1309804.4
B30: Resultados Transitados | E30: 14 | F30: =-'Blnct AR'!I2194 -> -22179622 | G30: =-'Blnct AR'!E2213+-'Blnct AR'!E2217+-'Blnct AR'!E2219 -> -30112421
B31: Resultados do Exercicio | F31: =-'Blnct AR'!I2252 -> -14501165 | G31: =-'Blnct AR'!E2215 -> 7932798.8
D32: Total do Capital Próprio | F32: =SUM(F28:F31) -> -17838343 | G32: =SUM(G28:G31) -> -3337177.8
B34: TOTAL DE CAPITAIS PRÓPRIOS | F34: =F32 -> -17838343 | G34: =G32 -> -3337177.8
B36: Passivo não Corrente
B37: Empréstimos de Médio e Longo Prazo | E37: 15 | F37: =-IF('Blnct AR'!I1014<0,'Blnct AR'!I1014,0) -> 0 | G37: =-IF('Blnct AR'!E1014<0,'Blnct AR'!E1014,0) -> 0
B38: Impostos diferidos | E38: 16 | F38: 0 | G38: 0
B39: Provisões para pensões | E39: 17 | F39: =-(IF('Blnct AR'!I1442<0,'Blnct AR'!I1442,0)) -> 0 | G39: =-(IF('Blnct AR'!E1442<0,'Blnct AR'!E1442,0)) -> 0
B40: ='Blnct AR'!D1451 -> Provisões p/ outros riscos e encargos | E40: 18 | F40: =-(IF('Blnct AR'!I1451<0,'Blnct AR'!I1451,0)) -> 0 | G40: =-(IF('Blnct AR'!E1451<0,'Blnct AR'!E1451,0)) -> 0
B41: Outros passivos não correntes | E41: 19 | F41: 0 | G41: 0
D42: Total do Passivo não Corrente | F42: =SUM(F37:F41) -> 0 | G42: =SUM(G37:G41) -> 0
B44: Passivo Corrente
B45: Contas a Pagar | E45: 19 | F45: =-(IF('Blnct AR'!I694<0,'Blnct AR'!I694,0)+IF('Blnct AR'!I1036<0,'Blnct AR'!I1036,0)+IF('Blnct AR'!I1135<0,'Blnct AR'!I1135,0)+IF('Blnct AR'!I1181<0,'Blnct AR'!I1181,0)) -> 3.7444576e+08 | G45: =-(IF('Blnct AR'!E694<0,'Blnct AR'!E694,0)+IF('Blnct AR'!E1036<0,'Blnct AR'!E1036,0)+IF('Blnct AR'!E1135<0,'Blnct AR'!E1135,0)+IF('Blnct AR'!E1181<0,'Blnct AR'!E1181,0)) -> 2.66902e+08
B46: Empréstimos de Curto Prazo | E46: 20 | F46: =IF('Blnct AR'!E1009<0,'Blnct AR'!E1009,0) -> 0 | G46: =IF('Blnct AR'!E1009<0,'Blnct AR'!E1009,0) -> 0
B47: Outros Passivos Correntes | E47: 19 | F47: =-(IF('Blnct AR'!I1245<0,'Blnct AR'!I1245,0)+IF('Blnct AR'!I1267<0,'Blnct AR'!I1267,0)+IF('Blnct AR'!I1280<0,'Blnct AR'!I1280,0)+IF('Blnct AR'!I1284<0,'Blnct AR'!I1284,0)+IF('Blnct AR'!I1294<0,'Blnct AR'!I1294,0)+IF('Blnct AR'!I1302<0,'Blnct AR'!I1302,0)+IF('Blnct AR'!I1309<0,'Blnct AR'!I1309,0)+IF('Blnct AR'!I1311<0,'Blnct AR'!I1311,0+IF('Blnct AR'!I1321<0,'Blnct AR'!I1321,0))) -> 11672383 | G47: =-(IF('Blnct AR'!E1245<0,'Blnct AR'!E1245,0)+IF('Blnct AR'!E1267<0,'Blnct AR'!E1267,0)+IF('Blnct AR'!E1280<0,'Blnct AR'!E1280,0)+IF('Blnct AR'!E1284<0,'Blnct AR'!E1284,0)+IF('Blnct AR'!E1294<0,'Blnct AR'!E1294,0)+IF('Blnct AR'!E1302<0,'Blnct AR'!E1302,0)+IF('Blnct AR'!E1309<0,'Blnct AR'!E1309,0)+IF('Blnct AR'!E1311<0,'Blnct AR'!E1311,0+IF('Blnct AR'!E1321<0,'Blnct AR'!E1321,0))) -> 11672383
D48: Total do Passivo Corrente | F48: =SUM(F45:F47) -> 3.8611814e+08 | G48: =SUM(G45:G47) -> 2.7857438e+08
...

Sheet D R
G1: =DBase!C6 -> Mbolo Yeto
B3: =DBase!B17 -> DEMONSTRAÇÃO DE RESULTADOS EM
B4: =DBase!F15 -> 46022
G6: Valores expressos em AKZ
B7: Designção | E7: Notas | F7: Exercicios
F8: =DBase!C4 -> 45658 | G8: =F8-1 -> 45657
B10: Vendas | E10: 22 | F10: =-'Blnct AR'!H2222 -> 82553815 | G10: 1.5561823e+08
B11: Prestação de Serviços | E11: 23 | F11: =-'Blnct AR'!H2223 -> 2.1847371e+08 | G11: 0
B12: Outros Proveitos | E12: 24 | F12: =-'Blnct AR'!H2224 -> 0 | G12: 1033342.2
D14: Total dos Proveitos e Ganhos Operacionais | F14: =SUM(F10:F12) -> 3.0102752e+08 | G14: =SUM(G10:G12) -> 1.5665157e+08
B16: Variação nos Prod. Acab. e em vias de fabr. | E16: 25 | F16: =-'Blnct AR'!H2225 -> 0 | G16: =-'Blnct AR'!E2225 -> 0
B17: Trabalhos para a Própria Empresa | E17: 26 | F17: =-'Blnct AR'!H2226 -> 0 | G17: =-'Blnct AR'!E2226 -> 0
B18: Custo das Exist. Vend. e das Mat-prim Cons. | E18: 27 | F18: =-'Blnct AR'!H2227 -> -48496258 | G18: -1.0563901e+08
B19: Custo com o pessoal | E19: 28 | F19: =-'Blnct AR'!H2228 -> -33038303 | G19: -29405897
B20: Amortizações | E20: 29 | F20: =-'Blnct AR'!H2229 -> 0 | G20: -12554881
B21: Outros Custos e perdas operacionais | E21: 30 | F21: =-'Blnct AR'!H2230 -> -2.1985272e+08 | G21: -65717293
D23: Total dos Custos e Perdas Operacionais | F23: =SUM(F16:F21) -> -3.0138728e+08 | G23: =SUM(G16:G21) -> -2.1331708e+08
B25: Resultados Operacionais | F25: =F14+F23 -> -359754.27 | G25: -56665509
B26: Resultados Financeiros | E26: 31 | F26: =-'Blnct AR'!H2254 -> -89656 | G26: -2087859.3
B27: Resultados de Filiais e Associadas | E27: 32 | F27: ='Blnct AR'!H2255 -> 0 | G27: 0
B28: Resultados não operacionais | E28: 33 | F28: =-'Blnct AR'!H2256 -> -14051754 | G28: 17078659
B29: Resultado antes de Impostos | F29: =SUM(F25:F28) -> -14501165 | G29: -41674709
B30: Imposto sobre o Rendimento | E30: 35 | F30: =-IF(F29>0,F29*30%,0) -> 0 | G30: 0
B31: Resultados Líq. das Actividades Correntes | F31: =IF(F30>0,F29-F30,F29+F30) -> -14501165 | G31: -41674709
B33: RESULTADOS LÍQUIDOS DO EXERCíCIO | F33: =F31 -> -14501165 | G33: =G31 -> -41674709

Sheet NDF
B2: NOTAS ÀS DEMONSTRAÇÕES FINANCEIRAS

Sheet NB
B2: NOTAS AO BALANÇO
I4: Aplicável / Não Aplicável
B6: 4 | C6: Imobilizações corpóreas | I6: =IF(Balanço!F11>0.1*Balanço!F28,"Aplicável","Não Aplicável") -> Aplicável
B8: 5 | C8: Imobilizações incorpóreas | I8: =IF(Balanço!F12>0.1*Balanço!F24,"Aplicável","Não Aplicável") -> Não Aplicável
B10: 6 | C10: Investimentos em subsidiárias e associadas | I10: =IF(Balanço!F13>0.1*Balanço!F24,"Aplicável","Não Aplicável") -> Não Aplicável
B12: 7 | C12: Outros activos não correntes | I12: =IF(Balanço!F14>0.1*Balanço!F24,"Aplicável","Não Aplicável") -> Não Aplicável
B14: 8 | C14: Existências | I14: =IF(Balanço!F18>0.1*Balanço!F24,"Aplicável","Não Aplicável") -> Aplicável
B16: 9 | C16: Outros ativos correntes e contas a receber | I16: =IF(Balanço!F19>0.1*Balanço!F24,"Aplicável","Não Aplicável") -> Aplicável
B18: 10 | C18: Disponibilidades | I18: =IF(Balanço!F20>0.1*Balanço!F24,"Aplicável","Não Aplicável") -> Não Aplicável
B20: 11 | C20: Outros ativos correntes | I20: =IF(Balanço!F21>0.1*Balanço!F24,"Aplicável","Não Aplicável") -> Não Aplicável
B22: 12 | C22: Capital | I22: =IF(Balanço!F28>0.1*Balanço!F24,"Aplicável","Não Aplicável") -> Não Aplicável
B24: 13 | C24: Reservas | I24: =IF(Balanço!F29>0.1*Balanço!F24,"Aplicável","Não Aplicável") -> Não Aplicável
B26: 14 | C26: Resultados transitados | I26: =IF(Balanço!F30>0.1*Balanço!F24,"Aplicável","Não Aplicável") -> Não Aplicável
B28: 15 | C28: Empréstimos de Médio e Longo Prazo | I28: =IF(Balanço!F37>0.1*Balanço!F24,"Aplicável","Não Aplicável") -> Não Aplicável
B30: 16 | C30: Impostos diferidos | I30: =IF(Balanço!F41>0.1*Balanço!F24,"Aplicável","Não Aplicável") -> Não Aplicável
B32: 17 | C32: Provisões para pensões | I32: =IF(Balanço!F42>0.1*Balanço!F24,"Aplicável","Não Aplicável") -> Não Aplicável
B34: 18 | C34: Provisões p/ outros riscos e encargos | I34: =IF(Balanço!F45>0.1*Balanço!F24,"Aplicável","Não Aplicável") -> Aplicável
B36: 19 | C36: Contas a Pagar | I36: =IF(Balanço!F49>0.1*Balanço!F24,"Aplicável","Não Aplicável") -> Não Aplicável
B38: 20 | C38: Empréstimos de Curto Prazo | I38: =IF(Balanço!F46>0.1*Balanço!F24,"Aplicável","Não Aplicável") -> Não Aplicável
B40: 21 | C40: Outros Passivos Correntes | I40: =IF(Balanço!F47>0.1*Balanço!F24,"Aplicável","Não Aplicável") -> Não Aplicável

Sheet NDR
B2: NOTAS À DEMONSTRAÇÃO DOS RESULTADOS
I4: Aplicável / Não Aplicável
B6: 22 | C6: Vendas | I6: =IF('D R'!F10>0.05*'D R'!F14,"Aplicável","Não Aplicável") -> Aplicável
B8: 23 | C8: Prestação de serviços | I8: =IF('D R'!F11>0.05*'D R'!F14,"Aplicável","Não Aplicável") -> Aplicável
B10: 24 | C10: Outros proveitos operacionais | I10: =IF('D R'!F12>0.05*'D R'!F14,"Aplicável","Não Aplicável") -> Não Aplicável
B12: 25 | C12: Variação nos prod. acab. e em vias de fabrico | I12: =IF('D R'!F16>0.05*'D R'!F14,"Aplicável","Não Aplicável") -> Não Aplicável
B14: 26 | C14: Trabalhos para a própria empresa | I14: =IF('D R'!F17>0.05*'D R'!F14,"Aplicável","Não Aplicável") -> Não Aplicável
B16: 27 | C16: Custos das merc. Vendidas e das mat. Consumidas | I16: =IF('D R'!F18>0.05*'D R'!F14,"Aplicável","Não Aplicável") -> Não Aplicável
B18: 28 | C18: Custos com pessoal | I18: =IF('D R'!F19>0.05*'D R'!F14,"Aplicável","Não Aplicável") -> Não Aplicável
B20: 29 | C20: Amortizações | I20: =IF('D R'!F20>0.05*'D R'!F14,"Aplicável","Não Aplicável") -> Não Aplicável
B22: 30 | C22: Outros custos e perdas operacionais | I22: =IF('D R'!F21>0.05*'D R'!F14,"Aplicável","Não Aplicável") -> Não Aplicável
B24: 31 | C24: Resultados financeiros | I24: =IF('D R'!F26>0.05*'D R'!F14,"Aplicável","Não Aplicável") -> Não Aplicável
B26: 32 | C26: Resultados de filiais e associadas | I26: =IF('D R'!F275%*'D R'!F14,"Aplicável","Não Aplicável") -> Não Aplicável
B28: 33 | C28: Resultados não operacionais | I28: =IF('D R'!F28>0.05*'D R'!F14,"Aplicável","Não Aplicável") -> Não Aplicável
B30: 34 | C30: Resultado Extraordinários | I30: =IF('D R'!F32>0.05*'D R'!F14,"Aplicável","Não Aplicável") -> Não Aplicável
B32: 35 | C32: Imposto sobre o Rendimento | I32: =IF('D R'!F30>0.05*'D R'!F14,"Aplicável","Não Aplicável") -> Não Aplicável

Sheet NB4 IC
A2: 4 | B2: Imobilizações corpóreas
A4: 4.1 | B4: Composição
B6: Rubricas | F6: Valor Bruto | H6: Amortizações Acumuladas | J6: Valor Líquido
B7: Terrenos e Recursos Naturais | F7: ='Blnct AR'!E7 -> 0 | H7: =-'Blnct AR'!I104 -> 0 | J7: =F7-H7 -> 0
B8: Edificios e outras Construções | F8: ='Blnct AR'!E15 -> 33771041 | H8: =-'Blnct AR'!I105 -> 23837407 | J8: =F8-H8 -> 9933633.3
B9: Equipamento básico | F9: ='Blnct AR'!I23 -> 16670973 | H9: =-'Blnct AR'!I106 -> 7966128.4 | J9: =F9-H9 -> 8704844.7
B10: Equipamento de carga e transporte | F10: ='Blnct AR'!E31 -> 30341500 | H10: =-'Blnct AR'!I107 -> 26408167 | J10: =F10-H10 -> 3933333.3
B11: Equipamento administrativo | F11: ='Blnct AR'!I44 -> 7513156.9 | H11: =-'Blnct AR'!I110 -> 4654722.3 | J11: =F11-H11 -> 2858434.6
B12: Taras e vasilhame | F12: ='Blnct AR'!E52 -> 0 | H12: =-'Blnct AR'!F116 -> 0 | J12: =F12-H12 -> 0
B13: Outras imobilizações corpóreas | F13: ='Blnct AR'!E55 -> 117408.44 | H13: =-'Blnct AR'!$I$117 -> 86451 | J13: =F13-H13 -> 30957.44
B14: Imobilizações em curso | F14: ='Blnct AR'!E91 -> 0 | J14: =F14-H14 -> 0
B15: Adiantamentos p/conta imob.corporeo | F15: ='Blnct AR'!E94 -> 0 | J15: =F15-H15 -> 0
B16: Total | F16: =SUM(F7:G15) -> 88414079 | H16: =SUM(H7:I15) -> 62952876 | J16: =SUM(J7:K14) -> 25461203
A18: 4.2 | B18: Movimentos, ocorridos durante o exercício, no valor bruto
B20: Rubricas | F20: Saldo Inicial | H20: Reavaliações | J20: Aumentos | L20: Alienações | N20: Transf. / Abates | P20: Saldo Final
B21: Terrenos e Recursos Naturais | F21: ='Blnct AR'!E7 -> 0 | H21: ='Blnct AR'!F7 -> 0 | J21: ='Blnct AR'!F7 -> 0 | L21: ='Blnct AR'!G7 -> 0 | N21: ='Blnct AR'!$F$2158 -> 0 | P21: =F21+H21+J21-L21-N21 -> 0
B22: Edificios e outras Construções | F22: ='Blnct AR'!E15 -> 33771041 | J22: ='Blnct AR'!F15 -> 0 | L22: ='Blnct AR'!G15 -> 0 | N22: 0 | P22: =F22+H22+J22-L22-N22 -> 33771041
B23: Equipamento básico | F23: ='Blnct AR'!E23 -> 15470973 | J23: ='Blnct AR'!F23 -> 1200000 | L23: ='Blnct AR'!G23 -> 0 | N23: 0 | P23: =F23+H23+J23-L23-N23 -> 16670973
B24: Equipamento de carga e transporte | F24: ='Blnct AR'!E31 -> 30341500 | J24: ='Blnct AR'!F31 -> 13611616 | L24: ='Blnct AR'!G31 -> 0 | N24: 0 | P24: =F24+H24+J24-L24-N24 -> 43953116
B25: Equipamento administrativo | F25: ='Blnct AR'!E44 -> 7084999.1 | J25: ='Blnct AR'!F44 -> 428157.75 | L25: ='Blnct AR'!G44 -> 0 | N25: 0 | P25: =F25+H25+J25-L25-N25 -> 7513156.9
B26: Taras e vasilhame | F26: ='Blnct AR'!E52 -> 0 | J26: ='Blnct AR'!F52 -> 0 | L26: ='Blnct AR'!G52 -> 0 | N26: 0 | P26: =F26+H26+J26-L26-N26 -> 0
B27: Outras imobilizações corpóreas | F27: ='Blnct AR'!E55 -> 117408.44 | J27: ='Blnct AR'!F55 -> 0 | L27: ='Blnct AR'!G55 -> 0 | N27: 0 | P27: =F27+H27+J27-L27-N27 -> 117408.44
B28: Imobilizações em curso | F28: ='Blnct AR'!E91 -> 0 | P28: =F28+H28+J28-L28-N28 -> 0
B29: Adiantamentos p/conta imob.corporeo | F29: ='Blnct AR'!E94 -> 0 | P29: =F29+H29+J29-L29-N29 -> 0
B30: Total | F30: =SUM(F21:G28) -> 86785921 | H30: =SUM(H21:I28) -> 0 | J30: =SUM(J21:K28) -> 15239773 | L30: =SUM(L21:M28) -> 0 | N30: =SUM(N21:O28) -> 0 | P30: =SUM(P21:Q28) -> 1.0202569e+08
A32: 4.3 | B32: Movimentos, ocorridos durante o exercício, nas amortizações acumuladas
B34: Rubricas | F34: Saldo Inicial | H34: Reavaliações | J34: Reforços | L34: Alienações | N34: Transferências Abates | P34: Saldo Final
B35: Terrenos e Recursos Naturais | F35: =-'Blnct AR'!E104 -> 0 | H35: ='Blnct AR'!G104 -> 0 | L35: ='Blnct AR'!G7 -> 0 | N35: 0 | P35: =F35+H35+J35-L35-N35 -> 0
B36: Edificios e outras Construções | F36: =-'Blnct AR'!E105 -> 23837407 | J36: ='Blnct AR'!F1920 -> 0 | L36: ='Blnct AR'!F105 -> 0 | N36: 0 | P36: =F36+H36+J36-L36-N36 -> 23837407
B37: Equipamento básico | F37: =-'Blnct AR'!E106 -> 7966128.4 | J37: ='Blnct AR'!F1921 -> 0 | L37: ='Blnct AR'!F106 -> 0 | N37: 0 | P37: =F37+H37+J37-L37-N37 -> 7966128.4
B38: Equipamento de carga e transporte | F38: =-'Blnct AR'!E107 -> 26408167 | J38: ='Blnct AR'!F1922 -> 0 | L38: ='Blnct AR'!F107 -> 0 | N38: 0 | P38: =F38+H38+J38-L38-N38 -> 26408167
B39: Equipamento administrativo | F39: =-'Blnct AR'!$E$110 -> 4654722.3 | J39: ='Blnct AR'!F1923 -> 0 | L39: ='Blnct AR'!F109 -> 0 | N39: 0 | P39: =F39+H39+J39-L39-N39 -> 4654722.3
B40: Taras e vasilhame | F40: =-'Blnct AR'!E116 -> 0 | J40: ='Blnct AR'!F1924 -> 0 | L40: ='Blnct AR'!F116 -> 0 | N40: 0
B41: Outras imobilizações corpóreas | F41: =-'Blnct AR'!E117 -> 86451 | J41: ='Blnct AR'!$G$117 -> 0 | L41: ='Blnct AR'!F117 -> 0 | N41: 0 | P41: =F41+H41+J41-L41-N41 -> 86451
B42: Total | F42: =SUM(F35:G41) -> 62952876 | H42: =SUM(H35:I41) -> 0 | J42: =SUM(J35:K41) -> 0 | L42: =SUM(L35:M41) -> 0 | N42: =SUM(N35:O41) -> 0 | P42: =SUM(P35:Q41) -> 62952876

Sheet NB5 IInc
A2: 5 | B2: Imobilizações Incorpóreas
A4: 5.1 | B4: Composição
B6: Rubricas | F6: Valor Bruto | H6: Amortizações Acumuladas | J6: Valor Líquido
B7: Trespasses | F7: ='Blnct AR'!E60 -> 0 | H7: ='Blnct AR'!E119 -> 0 | J7: =SUM(F7:I7) -> 0
B8: Desp.investiga. e desenvolvimento | F8: ='Blnct AR'!E62 -> 0 | H8: ='Blnct AR'!E120 -> 0 | J8: =SUM(F8:I8) -> 0
B9: Propriedade industrial e outros | F9: ='Blnct AR'!E64 -> 0 | H9: ='Blnct AR'!E121 -> 0 | J9: =SUM(F9:I9) -> 0
B10: Despesas de constituição | F10: ='Blnct AR'!E66 -> 4180500 | H10: ='Blnct AR'!E122 -> 0 | J10: =SUM(F10:I10) -> 4180500
B11: Outras imobilizações incorporeas | F11: ='Blnct AR'!E68 -> 1717400 | H11: ='Blnct AR'!I118 -> -5669341.6 | J11: =SUM(F11:I11) -> -3951941.6
B12: Total | F12: =SUM(F7:G11) -> 5897900 | H12: =SUM(H7:I11) -> -5669341.6 | J12: =SUM(J7:K11) -> 228558.36
A14: 5.2 | B14: Movimentos, ocorridos durante o exercício, no valor bruto
B16: Rubricas | F16: Saldo Inicial | H16: Aumentos | J16: Diminuições | L16: Saldo Final
B17: Trespasses | F17: ='Blnct AR'!E60 -> 0 | H17: ='Blnct AR'!F60 -> 0 | J17: ='Blnct AR'!G60 -> 0 | L17: =F17+H17-J17 -> 0
B18: Desp.investiga. e desenvolvimento | F18: ='Blnct AR'!E62 -> 0 | H18: ='Blnct AR'!F62 -> 0 | J18: ='Blnct AR'!G62 -> 0 | L18: =F18+H18-J18 -> 0
B19: Propriedade industrial e outros | F19: ='Blnct AR'!E64 -> 0 | H19: ='Blnct AR'!F64 -> 0 | J19: ='Blnct AR'!G64 -> 0 | L19: =F19+H19-J19 -> 0
B20: Despesas de constituição | F20: ='Blnct AR'!E66 -> 4180500 | H20: ='Blnct AR'!F66 -> 0 | J20: ='Blnct AR'!G66 -> 0 | L20: =F20+H20-J20 -> 4180500
B21: Outras imobilizações incorporeas | F21: ='Blnct AR'!E68 -> 1717400 | H21: ='Blnct AR'!F68 -> 0 | J21: ='Blnct AR'!G68 -> 0 | L21: =F21+H21-J21 -> 1717400
B22: Total | F22: =SUM(F17:G21) -> 5897900 | H22: =SUM(H17:I21) -> 0 | J22: =SUM(J17:K21) -> 0 | L22: =SUM(L17:M21) -> 5897900
A24: 5.3 | B24: Movimentos, ocorridos durante o exercício, nas amortizações acumuladas
B26: Rubricas | F26: Saldo Inicial | H26: Aumentos | J26: Diminuições | L26: Saldo Final
B27: Trespasses | F27: ='Blnct AR'!E119 -> 0 | H27: ='Blnct AR'!F1927 -> 0 | J27: ='Blnct AR'!G1927 -> 0 | L27: =F27+H27-J27 -> 0
B28: Desp.investiga. e desenvolvimento | F28: ='Blnct AR'!E120 -> 0 | H28: ='Blnct AR'!F1928 -> 0 | J28: ='Blnct AR'!G1928 -> 0 | L28: =F28+H28-J28 -> 0
B29: Propriedade industrial e outros | F29: ='Blnct AR'!E121 -> 0 | H29: ='Blnct AR'!F1929 -> 0 | J29: ='Blnct AR'!G1929 -> 0 | L29: =F29+H29-J29 -> 0
B30: Despesas de constituição | F30: ='Blnct AR'!E122 -> 0 | H30: ='Blnct AR'!F1930 -> 0 | J30: ='Blnct AR'!G1930 -> 0 | L30: =F30+H30-J30 -> 0
B31: Outras imobilizações incorporeas | F31: =-'Blnct AR'!E123 -> 5669341.6 | H31: ='Blnct AR'!F1931 -> 0 | J31: ='Blnct AR'!G1931 -> 0 | L31: =F31+H31-J31 -> 5669341.6
B32: Total | F32: =SUM(F27:G31) -> 5669341.6 | H32: =SUM(H27:I31) -> 0 | J32: =SUM(J27:K31) -> 0 | L32: =SUM(L27:M31) -> 5669341.6

Sheet NB8a19
A2: 8 | B2: Existências
A4: 8.1 | B4: Composição
B6: Rubricas | F6: Valor Bruto | H6: Provisões Acumuladas | J6: Valor Líquido
B7: Materias-primas, subs. e de consumo | F7: ='Blnct AR'!I308+'Blnct AR'!I148 -> 65207882 | J7: =F7+H7 -> 65207882
B8: Produtos e trabalhos em curso | F8: ='Blnct AR'!I325 -> 0 | J8: =F8+H8 -> 0
B9: Produtos acabados e intermédios | F9: ='Blnct AR'!I328 -> 0 | J9: =F9+H9 -> 0
B10: Sub-produtos, desp., resíd. e refugos | F10: ='Blnct AR'!I335 -> 0 | J10: =F10+H10 -> 0
B11: Mercadorias | F11: ='Blnct AR'!I340 -> 4500000 | J11: =F11+H11 -> 4500000
B12: Mat. primas, merc. e materiais em trans. | F12: ='Blnct AR'!I352 -> 11330087 | J12: =F12+H12 -> 11330087
B13: Total | F13: =SUM(F7:G12) -> 81037969 | H13: =SUM(H7:I12) -> 0 | J13: =SUM(J7:K12) -> 81037969
A15: 8.2 | B15: Movimentos, ocorridos durante o exercício, nas provisões
B17: Rubricas | F17: Saldo Inicial | H17: Aumentos | J17: Diminuições | L17: Saldo Final
B18: Materias-primas, subs. e de consumo | F18: ='Blnct AR'!E377 -> 0 | H18: ='Blnct AR'!F377 -> 0 | J18: ='Blnct AR'!G377 -> 0 | L18: =F18+H18-J18 -> 0
B19: Produtos e trabalhos em curso | F19: ='Blnct AR'!E379 -> 0 | H19: ='Blnct AR'!F379 -> 0 | J19: ='Blnct AR'!G379 -> 0 | L19: =F19+H19-J19 -> 0
B20: Produtos acabados e intermédios | F20: ='Blnct AR'!E381 -> 0 | H20: ='Blnct AR'!F381 -> 0 | J20: ='Blnct AR'!G381 -> 0 | L20: =F20+H20-J20 -> 0
B21: Sub-produtos, desp., resíd. e refugos | F21: ='Blnct AR'!E383 -> 0 | H21: ='Blnct AR'!F383 -> 0 | J21: ='Blnct AR'!G383 -> 0 | L21: =F21+H21-J21 -> 0
B22: Mercadorias | F22: ='Blnct AR'!E340 -> 0 | H22: ='Blnct AR'!F340 -> 4500000 | J22: ='Blnct AR'!G340 -> 0 | L22: =F22+H22-J22 -> 4500000
B23: Mat. primas, merc. e materiais em trans. | F23: 0 | H23: 0 | J23: 0 | L23: =F23+H23-J23 -> 0
B24: Total | F24: =SUM(F18:G23) -> 0 | H24: =SUM(H18:I23) -> 4500000 | J24: =SUM(J18:K23) -> 0 | L24: =SUM(L18:M23) -> 4500000
A26: 9 | B26: Outros activos correntes e contas a receber
B28: Rubricas | F28: Corrente | H28: Total
B29: Valor Bruto
B30: Clientes correntes | F30: =IF('Blnct AR'!I389>0,'Blnct AR'!I389,0) -> 1.8592921e+08 | H30: =F30 -> 1.8592921e+08
B31: Clientes-titulos a receber | F31: =IF('Blnct AR'!I522>0,'Blnct AR'!I522,0) -> 0 | H31: =F31 -> 0
B32: Clientes Retenções | F32: =IF('Blnct AR'!I556>0,'Blnct AR'!I556,0) -> 24840655 | H32: =F32 -> 24840655
B33: Clientes de cobrança duvidosa | F33: =IF('Blnct AR'!I574>0,'Blnct AR'!I574,0) -> 32608955 | H33: =F33 -> 32608955
B34: Fornecedores-saldos devedores | F34: =IF('Blnct AR'!I952>0,'Blnct AR'!I952,0)*0 -> 0 | H34: =F34 -> 0
B35: Estado | F35: =IF('Blnct AR'!I1036>0,'Blnct AR'!I1036,0) -> 0 | H35: =F35 -> 0
B36: Participantes e Participadas | F36: =IF('Blnct AR'!I1136>0,'Blnct AR'!I1136,0) -> 0 | H36: =F36 -> 0
B37: Pessoal | F37: =IF('Blnct AR'!I1181>0,'Blnct AR'!I1181,0) -> 0 | H37: =F37 -> 0
B38: Devedores - vendas de imobilizado | F38: =IF('Blnct AR'!I1267>0,'Blnct AR'!I1267,0) -> 0 | H38: =F38 -> 0
B39: Outros devedores | F39: =IF('Blnct AR'!I1321>0,'Blnct AR'!I1321,0) -> 0 | H39: =F39 -> 0
B40: Provisões para cobranças duvidosas | F40: ='Blnct AR'!$I$1429 -> -2919625.5 | H40: =F40 -> -2919625.5
B41: Total | F41: =SUM(F30:G40) -> 2.4045919e+08 | H41: =SUM(H30:I40) -> 2.4045919e+08
A43: 10 | B43: Disponibilidades
B45: Rubricas | F45: =DBase!C4 -> 45658 | H45: =F45-1 -> 45657
B46: Títulos Negociáveis | F46: ='Blnct AR'!I1454 -> 0 | H46: ='Blnct AR'!E1454 -> 0
B47: Depósitos a prazo | F47: ='Blnct AR'!I1465 -> 250000 | H47: ='Blnct AR'!E1465 -> 250000
B48: Depósitos à ordem | F48: ='Blnct AR'!I1476 -> 29822829 | H48: ='Blnct AR'!E1476 -> 95694617
B49: Caixa | F49: ='Blnct AR'!I1500 -> 335884.98 | H49: ='Blnct AR'!E1500 -> 3541747.6
...

Sheet NDR22a35
A2: 22 | B2: Vendas
B4: Rubricas | F4: =DBase!C4 -> 45658 | H4: =F4-1 -> 45657
B5: Mercado interno
B6: Vendas | F6: ='Blnct AR'!G1571 -> 95353815
B7: Subsídios a preços | F7: ='Blnct AR'!G1080 -> 0
B8: Mercado externo | F8: ='Blnct AR'!G1584 -> 0
B9: Total | F9: =SUM(F6:G8) -> 95353815
A11: 23 | B11: Prestação de serviços
B13: Rubricas | F13: =DBase!C4 -> 45658 | H13: =F13-1 -> 45657
B14: Mercado interno | F14: ='Blnct AR'!G1636 -> 2.1847371e+08
B15: Mercado externo | F15: ='Blnct AR'!G1637 -> 0
B16: Total | F16: =SUM(F14:G15) -> 2.1847371e+08 | H16: =SUM(H14:I15) -> 0
A18: 27 | B18: Custo das existências vendidas e das matérias-primas e subsidiárias consumidas
B20: Rubricas | F20: Existências iniciais | H20: Compras | J20: Ofertas e perdas ou ganhos | L20: Existências finais | N20: Custo no ano
B21: Matérias-primas, subsidiárias e de consumo | F21: ='Blnct AR'!E147 -> 40682932 | H21: =L21+N21-F21 -> 88851295 | J21: =SUM('Blnct AR'!I1742,'Blnct AR'!F2133) -> 0 | L21: ='Blnct AR'!$I$147 -> 81037969 | N21: ='Blnct AR'!$I$1807 -> 48496258
B22: Mercadorias | F22: ='Blnct AR'!E341 -> 0 | H22: ='Blnct AR'!F341 -> 4500000 | J22: =SUM('Blnct AR'!I2137,'Blnct AR'!I2060,'Blnct AR'!I1746) -> 0 | L22: ='Blnct AR'!I341 -> 4500000 | N22: =F22+H22-J22-L22 -> 0
B23: Total | F23: =SUM(F21:G22) -> 40682932 | H23: =SUM(H21:I22) -> 93351295 | J23: =SUM(J21:K22) -> 0 | L23: =SUM(L21:M22) -> 85537969 | N23: =SUM(N21:O22) -> 48496258
A25: 28 | B25: Custos com o pessoal
B27: Rubricas | F27: =DBase!C4 -> 45658 | H27: =F27-1 -> 45657
B28: Remunerações do pessoal | F28: =SUM('Blnct AR'!F1831,'Blnct AR'!F1879) -> 28034340
B29: Seguros acidente trab.doenç.prof. | F29: ='Blnct AR'!F1883 -> 0
B30: Formação | F30: ='Blnct AR'!F1888 -> 0
B31: Outros despesas com pessoal | F31: ='Blnct AR'!F1893 -> 5003962.5
B32: Total | F32: =SUM(F28:G31) -> 33038303 | H32: =SUM(H30:I31) -> 0
H33: =DBase!D12 -> 1
A35: 30 | B35: Outros custos e perdas operacionais
B37: Rubricas | F37: =DBase!C4 -> 45658 | H37: =F37-1 -> 45657
B38: Subcontratos | F38: ='Blnct AR'!I1934 -> 51542270
B39: Fornecimento e serviço de terceiros | F39: ='Blnct AR'!I2016+'Blnct AR'!I2026+'Blnct AR'!I2038 -> 92283684
B40: Água e Combustíveis | F40: ='Blnct AR'!$I$1946 -> 2072681.3
B41: Conservação e reparação | F41: ='Blnct AR'!I1955+'Blnct AR'!I1995 -> 38729353
B42: Comunicação | F42: ='Blnct AR'!$I$1969 -> 1459803.5
B43: Rendas e alugueres | F43: ='Blnct AR'!$I$1974 -> 14179508
B44: Seguros | F44: ='Blnct AR'!$I$1982 -> 972249.06
B45: Deslocações e estadas | F45: ='Blnct AR'!I1987 -> 12749394
B46: Impostos | F46: ='Blnct AR'!I2040 -> 1752340
B47: Ofertas e amostras de existências | F47: ='Blnct AR'!I2060 -> 0
B48: Custos e perdas operacionais | F48: ='Blnct AR'!I2061 -> 0
B49: Total | F49: =SUM(F38:G48) -> 2.1574128e+08 | H49: =SUM(H40:I48,H38) -> 0
A51: 31 | B51: Resultados financeiros
...

Sheet Flx CX
G1: =#REF! -> #REF!
B3: =#REF! -> #REF!
B4: =#REF! -> #REF!
G6: Valores expressos em AKZ
B7: Designção | E7: Notas | F7: Exercicios
F8: 2015 | G8: 2014
B9: Fluxo de caixa das atividades operacionais
B10: Recebimentos de Clientes
B11: Pagamentos a fornecedores e empregados
